[2025-04-09T11:47:30.706+0000] {local_task_job_runner.py:123} INFO - ::group::Pre task execution logs
[2025-04-09T11:47:30.922+0000] {taskinstance.py:2614} INFO - Dependencies all met for dep_context=non-requeueable deps ti=<TaskInstance: orchestation.work_1 scheduled__2025-03-18T00:00:00+00:00 [queued]>
[2025-04-09T11:47:31.176+0000] {taskinstance.py:2614} INFO - Dependencies all met for dep_context=requeueable deps ti=<TaskInstance: orchestation.work_1 scheduled__2025-03-18T00:00:00+00:00 [queued]>
[2025-04-09T11:47:31.197+0000] {taskinstance.py:2867} INFO - Starting attempt 1 of 1
[2025-04-09T11:47:31.484+0000] {taskinstance.py:2890} INFO - Executing <Task(BashOperator): work_1> on 2025-03-18 00:00:00+00:00
[2025-04-09T11:47:31.671+0000] {warnings.py:112} WARNING - /home/***/.local/lib/python3.12/site-packages/***/task/task_runner/standard_task_runner.py:70: DeprecationWarning: This process (pid=1450) is multi-threaded, use of fork() may lead to deadlocks in the child.
  pid = os.fork()

[2025-04-09T11:47:31.686+0000] {standard_task_runner.py:72} INFO - Started process 1459 to run task
[2025-04-09T11:47:31.687+0000] {standard_task_runner.py:104} INFO - Running: ['***', 'tasks', 'run', 'orchestation', 'work_1', 'scheduled__2025-03-18T00:00:00+00:00', '--job-id', '15', '--raw', '--subdir', 'DAGS_FOLDER/orchestation.py', '--cfg-path', '/tmp/tmppbgfny3_']
[2025-04-09T11:47:31.707+0000] {standard_task_runner.py:105} INFO - Job 15: Subtask work_1
[2025-04-09T11:47:32.160+0000] {task_command.py:467} INFO - Running <TaskInstance: orchestation.work_1 scheduled__2025-03-18T00:00:00+00:00 [running]> on host e8bb6e8ec07a
[2025-04-09T11:47:32.758+0000] {taskinstance.py:3134} INFO - Exporting env vars: AIRFLOW_CTX_DAG_OWNER='***' AIRFLOW_CTX_DAG_ID='orchestation' AIRFLOW_CTX_TASK_ID='work_1' AIRFLOW_CTX_EXECUTION_DATE='2025-03-18T00:00:00+00:00' AIRFLOW_CTX_TRY_NUMBER='1' AIRFLOW_CTX_DAG_RUN_ID='scheduled__2025-03-18T00:00:00+00:00'
[2025-04-09T11:47:32.779+0000] {taskinstance.py:732} INFO - ::endgroup::
[2025-04-09T11:47:32.977+0000] {subprocess.py:78} INFO - Tmp dir root location: /tmp
[2025-04-09T11:47:33.031+0000] {subprocess.py:88} INFO - Running command: ['/usr/bin/bash', '-c', "sleep 2 && echo 'work_1"]
[2025-04-09T11:47:33.153+0000] {subprocess.py:99} INFO - Output:
[2025-04-09T11:47:33.168+0000] {subprocess.py:106} INFO - /usr/bin/bash: -c: line 1: unexpected EOF while looking for matching `''
[2025-04-09T11:47:33.184+0000] {subprocess.py:110} INFO - Command exited with return code 2
[2025-04-09T11:47:33.248+0000] {taskinstance.py:3313} ERROR - Task failed with exception
Traceback (most recent call last):
  File "/home/airflow/.local/lib/python3.12/site-packages/airflow/models/taskinstance.py", line 768, in _execute_task
    result = _execute_callable(context=context, **execute_callable_kwargs)
             ^^^^^^^^^^^^^^^^^^^^^^^^^^^^^^^^^^^^^^^^^^^^^^^^^^^^^^^^^^^^^
  File "/home/airflow/.local/lib/python3.12/site-packages/airflow/models/taskinstance.py", line 734, in _execute_callable
    return ExecutionCallableRunner(
           ^^^^^^^^^^^^^^^^^^^^^^^^
  File "/home/airflow/.local/lib/python3.12/site-packages/airflow/utils/operator_helpers.py", line 252, in run
    return self.func(*args, **kwargs)
           ^^^^^^^^^^^^^^^^^^^^^^^^^^
  File "/home/airflow/.local/lib/python3.12/site-packages/airflow/models/baseoperator.py", line 424, in wrapper
    return func(self, *args, **kwargs)
           ^^^^^^^^^^^^^^^^^^^^^^^^^^^
  File "/home/airflow/.local/lib/python3.12/site-packages/airflow/operators/bash.py", line 276, in execute
    raise AirflowException(
airflow.exceptions.AirflowException: Bash command failed. The command returned a non-zero exit code 2.
[2025-04-09T11:47:33.297+0000] {taskinstance.py:1226} INFO - Marking task as FAILED. dag_id=orchestation, task_id=work_1, run_id=scheduled__2025-03-18T00:00:00+00:00, execution_date=20250318T000000, start_date=20250409T114730, end_date=20250409T114733
[2025-04-09T11:47:33.696+0000] {taskinstance.py:341} INFO - ::group::Post task execution logs
[2025-04-09T11:47:33.705+0000] {standard_task_runner.py:124} ERROR - Failed to execute job 15 for task work_1 (Bash command failed. The command returned a non-zero exit code 2.; 1459)
Traceback (most recent call last):
  File "/home/airflow/.local/lib/python3.12/site-packages/airflow/task/task_runner/standard_task_runner.py", line 117, in _start_by_fork
    ret = args.func(args, dag=self.dag)
          ^^^^^^^^^^^^^^^^^^^^^^^^^^^^^
  File "/home/airflow/.local/lib/python3.12/site-packages/airflow/cli/cli_config.py", line 49, in command
    return func(*args, **kwargs)
           ^^^^^^^^^^^^^^^^^^^^^
  File "/home/airflow/.local/lib/python3.12/site-packages/airflow/utils/cli.py", line 116, in wrapper
    return f(*args, **kwargs)
           ^^^^^^^^^^^^^^^^^^
  File "/home/airflow/.local/lib/python3.12/site-packages/airflow/cli/commands/task_command.py", line 483, in task_run
    task_return_code = _run_task_by_selected_method(args, _dag, ti)
                       ^^^^^^^^^^^^^^^^^^^^^^^^^^^^^^^^^^^^^^^^^^^^
  File "/home/airflow/.local/lib/python3.12/site-packages/airflow/cli/commands/task_command.py", line 256, in _run_task_by_selected_method
    return _run_raw_task(args, ti)
           ^^^^^^^^^^^^^^^^^^^^^^^
  File "/home/airflow/.local/lib/python3.12/site-packages/airflow/cli/commands/task_command.py", line 341, in _run_raw_task
    return ti._run_raw_task(
           ^^^^^^^^^^^^^^^^^
  File "/home/airflow/.local/lib/python3.12/site-packages/airflow/utils/session.py", line 97, in wrapper
    return func(*args, session=session, **kwargs)
           ^^^^^^^^^^^^^^^^^^^^^^^^^^^^^^^^^^^^^^
  File "/home/airflow/.local/lib/python3.12/site-packages/airflow/models/taskinstance.py", line 3006, in _run_raw_task
    return _run_raw_task(
           ^^^^^^^^^^^^^^
  File "/home/airflow/.local/lib/python3.12/site-packages/airflow/models/taskinstance.py", line 274, in _run_raw_task
    TaskInstance._execute_task_with_callbacks(
  File "/home/airflow/.local/lib/python3.12/site-packages/airflow/models/taskinstance.py", line 3161, in _execute_task_with_callbacks
    result = self._execute_task(context, task_orig)
             ^^^^^^^^^^^^^^^^^^^^^^^^^^^^^^^^^^^^^^
  File "/home/airflow/.local/lib/python3.12/site-packages/airflow/models/taskinstance.py", line 3185, in _execute_task
    return _execute_task(self, context, task_orig)
           ^^^^^^^^^^^^^^^^^^^^^^^^^^^^^^^^^^^^^^^
  File "/home/airflow/.local/lib/python3.12/site-packages/airflow/models/taskinstance.py", line 768, in _execute_task
    result = _execute_callable(context=context, **execute_callable_kwargs)
             ^^^^^^^^^^^^^^^^^^^^^^^^^^^^^^^^^^^^^^^^^^^^^^^^^^^^^^^^^^^^^
  File "/home/airflow/.local/lib/python3.12/site-packages/airflow/models/taskinstance.py", line 734, in _execute_callable
    return ExecutionCallableRunner(
           ^^^^^^^^^^^^^^^^^^^^^^^^
  File "/home/airflow/.local/lib/python3.12/site-packages/airflow/utils/operator_helpers.py", line 252, in run
    return self.func(*args, **kwargs)
           ^^^^^^^^^^^^^^^^^^^^^^^^^^
  File "/home/airflow/.local/lib/python3.12/site-packages/airflow/models/baseoperator.py", line 424, in wrapper
    return func(self, *args, **kwargs)
           ^^^^^^^^^^^^^^^^^^^^^^^^^^^
  File "/home/airflow/.local/lib/python3.12/site-packages/airflow/operators/bash.py", line 276, in execute
    raise AirflowException(
airflow.exceptions.AirflowException: Bash command failed. The command returned a non-zero exit code 2.
[2025-04-09T11:47:33.754+0000] {local_task_job_runner.py:266} INFO - Task exited with return code 1
[2025-04-09T11:47:33.844+0000] {taskinstance.py:3901} INFO - 0 downstream tasks scheduled from follow-on schedule check
[2025-04-09T11:47:33.877+0000] {local_task_job_runner.py:245} INFO - ::endgroup::
